test_add_two_negative (class_1027_unittest.class_01.TestMathMenthod) ... ok
test_add_two_positive (class_1027_unittest.class_01.TestMathMenthod) ... FAIL
test_add_two_zero (class_1027_unittest.class_01.TestMathMenthod) ... ok

======================================================================
FAIL: test_add_two_positive (class_1027_unittest.class_01.TestMathMenthod)
----------------------------------------------------------------------
Traceback (most recent call last):
  File "D:\Pycharm\lemon11\class_1027_unittest\class_01.py", line 30, in test_add_two_positive
    self.assertEqual(3,res,'**两个正数相加出错了**') # 断言里面，msg是用例执行失败才会提示
AssertionError: 3 != 2 : **两个正数相加出错了**

----------------------------------------------------------------------
Ran 3 tests in 0.001s

FAILED (failures=1)
